ERROR:force_wfmanager.wfmanager_task:Error when saving workflow
Traceback (most recent call last):
  File "/Users/sborini/Work/github/force-h2020/force-wfmanager/force_wfmanager/wfmanager_task.py", line 192, in _write_workflow
    with open(file_path, 'w') as output:
  File "/Users/sborini/.edm/envs/force36/lib/python3.6/site-packages/mock/mock.py", line 1062, in __call__
    return _mock_self._mock_call(*args, **kwargs)
  File "/Users/sborini/.edm/envs/force36/lib/python3.6/site-packages/mock/mock.py", line 1118, in _mock_call
    raise effect
Exception: OUPS
ERROR:force_wfmanager.wfmanager_task:Error when saving workflow
Traceback (most recent call last):
  File "/Users/sborini/Work/github/force-h2020/force-wfmanager/force_wfmanager/wfmanager_task.py", line 192, in _write_workflow
    with open(file_path, 'w') as output:
  File "/Users/sborini/.edm/envs/force36/lib/python3.6/site-packages/mock/mock.py", line 1062, in __call__
    return _mock_self._mock_call(*args, **kwargs)
  File "/Users/sborini/.edm/envs/force36/lib/python3.6/site-packages/mock/mock.py", line 1118, in _mock_call
    raise effect
OSError: OUPS
ERROR:force_wfmanager.wfmanager_task:Unable to delete temporary workflow file at /var/folders/wj/t853fk6n3blbkpx7lvljsffw0000gp/T/tmpugtxin07
Traceback (most recent call last):
  File "/Users/sborini/Work/github/force-h2020/force-wfmanager/force_wfmanager/wfmanager_task.py", line 333, in _clean_tmp_workflow
    os.remove(workflow_path)
FileNotFoundError: [Errno 2] No such file or directory: '/var/folders/wj/t853fk6n3blbkpx7lvljsffw0000gp/T/tmpugtxin07'
ERROR:force_wfmanager.wfmanager_task:Unknown exception occurred while invoking force bdss executable.
Traceback (most recent call last):
  File "/Users/sborini/Work/github/force-h2020/force-wfmanager/force_wfmanager/wfmanager_task.py", line 301, in _execute_bdss
    subprocess.check_call([self._bdss_executable_path, workflow_path])
  File "/Users/sborini/.edm/envs/force36/lib/python3.6/site-packages/mock/mock.py", line 1062, in __call__
    return _mock_self._mock_call(*args, **kwargs)
  File "/Users/sborini/.edm/envs/force36/lib/python3.6/site-packages/mock/mock.py", line 1118, in _mock_call
    raise effect
Exception: boom
ERROR:force_wfmanager.wfmanager_task:Unable to delete temporary workflow file at /var/folders/wj/t853fk6n3blbkpx7lvljsffw0000gp/T/tmpi5xiw3un
Traceback (most recent call last):
  File "/Users/sborini/Work/github/force-h2020/force-wfmanager/force_wfmanager/wfmanager_task.py", line 301, in _execute_bdss
    subprocess.check_call([self._bdss_executable_path, workflow_path])
  File "/Users/sborini/.edm/envs/force36/lib/python3.6/site-packages/mock/mock.py", line 1062, in __call__
    return _mock_self._mock_call(*args, **kwargs)
  File "/Users/sborini/.edm/envs/force36/lib/python3.6/site-packages/mock/mock.py", line 1118, in _mock_call
    raise effect
Exception: boom

During handling of the above exception, another exception occurred:

Traceback (most recent call last):
  File "/Users/sborini/Work/github/force-h2020/force-wfmanager/force_wfmanager/wfmanager_task.py", line 333, in _clean_tmp_workflow
    os.remove(workflow_path)
FileNotFoundError: [Errno 2] No such file or directory: '/var/folders/wj/t853fk6n3blbkpx7lvljsffw0000gp/T/tmpi5xiw3un'
ERROR:force_wfmanager.wfmanager_task:force_bdss returned a non-zero value after execution
Traceback (most recent call last):
  File "/Users/sborini/Work/github/force-h2020/force-wfmanager/force_wfmanager/wfmanager_task.py", line 301, in _execute_bdss
    subprocess.check_call([self._bdss_executable_path, workflow_path])
  File "/Users/sborini/.edm/envs/force36/lib/python3.6/site-packages/mock/mock.py", line 1062, in __call__
    return _mock_self._mock_call(*args, **kwargs)
  File "/Users/sborini/.edm/envs/force36/lib/python3.6/site-packages/mock/mock.py", line 1118, in _mock_call
    raise effect
subprocess.CalledProcessError: Command 'fake_command' returned non-zero exit status 1.
ERROR:force_wfmanager.wfmanager_task:Unable to delete temporary workflow file at /var/folders/wj/t853fk6n3blbkpx7lvljsffw0000gp/T/tmpb6huq2m7
Traceback (most recent call last):
  File "/Users/sborini/Work/github/force-h2020/force-wfmanager/force_wfmanager/wfmanager_task.py", line 301, in _execute_bdss
    subprocess.check_call([self._bdss_executable_path, workflow_path])
  File "/Users/sborini/.edm/envs/force36/lib/python3.6/site-packages/mock/mock.py", line 1062, in __call__
    return _mock_self._mock_call(*args, **kwargs)
  File "/Users/sborini/.edm/envs/force36/lib/python3.6/site-packages/mock/mock.py", line 1118, in _mock_call
    raise effect
subprocess.CalledProcessError: Command 'fake_command' returned non-zero exit status 1.

During handling of the above exception, another exception occurred:

Traceback (most recent call last):
  File "/Users/sborini/Work/github/force-h2020/force-wfmanager/force_wfmanager/wfmanager_task.py", line 333, in _clean_tmp_workflow
    os.remove(workflow_path)
FileNotFoundError: [Errno 2] No such file or directory: '/var/folders/wj/t853fk6n3blbkpx7lvljsffw0000gp/T/tmpb6huq2m7'
ERROR:force_wfmanager.wfmanager_task:Error while executing force_bdss executable.  Is force_bdss in your path?
Traceback (most recent call last):
  File "/Users/sborini/Work/github/force-h2020/force-wfmanager/force_wfmanager/wfmanager_task.py", line 301, in _execute_bdss
    subprocess.check_call([self._bdss_executable_path, workflow_path])
  File "/Users/sborini/.edm/envs/force36/lib/python3.6/site-packages/mock/mock.py", line 1062, in __call__
    return _mock_self._mock_call(*args, **kwargs)
  File "/Users/sborini/.edm/envs/force36/lib/python3.6/site-packages/mock/mock.py", line 1118, in _mock_call
    raise effect
OSError: whatever
ERROR:force_wfmanager.wfmanager_task:Unable to delete temporary workflow file at /var/folders/wj/t853fk6n3blbkpx7lvljsffw0000gp/T/tmp41u0t9xm
Traceback (most recent call last):
  File "/Users/sborini/Work/github/force-h2020/force-wfmanager/force_wfmanager/wfmanager_task.py", line 301, in _execute_bdss
    subprocess.check_call([self._bdss_executable_path, workflow_path])
  File "/Users/sborini/.edm/envs/force36/lib/python3.6/site-packages/mock/mock.py", line 1062, in __call__
    return _mock_self._mock_call(*args, **kwargs)
  File "/Users/sborini/.edm/envs/force36/lib/python3.6/site-packages/mock/mock.py", line 1118, in _mock_call
    raise effect
OSError: whatever

During handling of the above exception, another exception occurred:

Traceback (most recent call last):
  File "/Users/sborini/Work/github/force-h2020/force-wfmanager/force_wfmanager/wfmanager_task.py", line 333, in _clean_tmp_workflow
    os.remove(workflow_path)
FileNotFoundError: [Errno 2] No such file or directory: '/var/folders/wj/t853fk6n3blbkpx7lvljsffw0000gp/T/tmp41u0t9xm'
ERROR:root:Unable to run BDSS.
Traceback (most recent call last):
  File "/Users/sborini/Work/github/force-h2020/force-wfmanager/force_wfmanager/wfmanager_task.py", line 284, in run_bdss
    WorkflowWriter().write(self.workflow_m, output)
  File "/Users/sborini/.edm/envs/force36/lib/python3.6/site-packages/mock/mock.py", line 1062, in __call__
    return _mock_self._mock_call(*args, **kwargs)
  File "/Users/sborini/.edm/envs/force36/lib/python3.6/site-packages/mock/mock.py", line 1118, in _mock_call
    raise effect
Exception: write failed
ERROR:force_wfmanager.wfmanager_task:Error when saving workflow
Traceback (most recent call last):
  File "/Users/sborini/Work/github/force-h2020/force-wfmanager/force_wfmanager/wfmanager_task.py", line 192, in _write_workflow
    with open(file_path, 'w') as output:
  File "/Users/sborini/.edm/envs/force36/lib/python3.6/site-packages/mock/mock.py", line 1062, in __call__
    return _mock_self._mock_call(*args, **kwargs)
  File "/Users/sborini/.edm/envs/force36/lib/python3.6/site-packages/mock/mock.py", line 1118, in _mock_call
    raise effect
Exception: OUPS
